Workbook

Sheet Ruta10
B1: PLANIFICACION SEMANAL
B2: VENDEDOR | C2: MARVIN COLOP
B3: RUTA | C3: XELA CENTRO
B4: SUPERVISOR | C4: IVAN FLORES
B7: SEMANA 1 | H7: kilometro promedios recorridos | K7: =+H14 -> 163 | L7: =+K7/33 -> 4.9393939 | M7: =+L7*28 -> 138.30303
H8: Kilometros | I8: Costo Gasolina | J8: Hotel | K8: Peaje | L8: Comida | M8: Totales
B9: LUNES | C9: ZONA 2 | H9: 22 | I9: =+H9/33*28 -> 18.666667 | M9: =+I9+J9+K9+L9 -> 18.666667
B10: MARTES | C10: ZONA 2 | H10: 22 | I10: =+H10/33*28 -> 18.666667 | L10: 50 | M10: =+I10+J10+K10+L10 -> 68.666667
B11: VIERNES | C11: OLINTEPEQUE -SIJA, SAN FRANCISCO LA UNION | H11: 72 | I11: =+H11/33*28 -> 61.090909 | L11: 50 | M11: =+I11+J11+K11+L11 -> 111.09091 | N11: CAMBIO REALIZADO 15/7/2023, OLINTEPE Y SIJA SE PASARA EL DIA MIERCOLES
B12: MIERCOLES | C12: ZONA 5 | H12: 19 | I12: =+H12/33*28 -> 16.121212 | L12: 50 | M12: =+I12+J12+K12+L12 -> 66.121212 | N12: PARA REALIZAR ENTREGAS EL DIA JUEVES DE LA SIGUIENTE SEMANA JUNTO A HUITAN Y CABRICAN
B13: JUEVES | C13: SALCAJA | H13: 28 | I13: =+H13/33*28 -> 23.757576 | L13: 50 | M13: =+I13+J13+K13+L13 -> 73.757576
H14: =SUM(H9:H13) -> 163 | I14: =SUM(I9:I13) -> 138.30303 | J14: =SUM(J9:J13) -> 0 | K14: =SUM(K9:K13) -> 0 | L14: =SUM(L9:L13) -> 200 | M14: =SUM(M9:M13) -> 338.30303
B17: SEMANA 2 | H17: kilometro promedios recorridos | K17: =+H24 -> 130 | L17: =+K17/33 -> 3.9393939 | M17: =+L17*28 -> 110.30303
H18: Kilometros | I18: Costo Gasolina | J18: Hotel | K18: Peaje | L18: Comida | M18: Totales | O18: LA RUTA SALE DE MIERCOLES A JUEVES
B19: LUNES | C19: ZONA 4 | H19: 36 | I19: =+H19/33*28 -> 30.545455 | L19: 50 | M19: =+I19+J19+K19+L19 -> 80.545455
B20: MARTES | C20: ZONA 1 | H20: 26 | I20: =+H20/33*28 -> 22.060606 | L20: 50 | M20: =+I20+J20+K20+L20 -> 72.060606
B21: MIERCOLES | C21: SALIDA Y ALMOLONGA | H21: 22 | I21: =+H21/33*28 -> 18.666667 | L21: 50 | M21: =+I21+J21+K21+L21 -> 68.666667
B22: JUEVES | C22: FABRICA DE CANTEL-CANTEL | H22: 8 | I22: =+H22/33*28 -> 6.7878788 | M22: =+I22+J22+K22+L22 -> 6.7878788 | O22: SE DESPACHA LO QUE COLOP VENDA HASTA EL DIA MIERCOLES, LO QUE VENDE EL JUEVES QUEDA PARA EL SIGUIENTE JUEVES
B23: VIERNES | C23: ZUNIL SANTA MARIA DE JESUS | H23: 38 | I23: =+H23/33*28 -> 32.242424 | L23: 50 | M23: =+I23+J23+K23+L23 -> 82.242424
H24: =SUM(H19:H23) -> 130 | I24: =SUM(I19:I23) -> 110.30303 | J24: =SUM(J19:J23) -> 0 | K24: =SUM(K19:K23) -> 0 | L24: =SUM(L19:L23) -> 200 | M24: =SUM(M19:M23) -> 310.30303
B27: SEMANA 3 | H27: kilometro promedios recorridos | K27: =+H34 -> 217 | L27: =+K27/33 -> 6.5757576 | M27: =+L27*28 -> 184.12121
H28: Kilometros | I28: Costo Gasolina | J28: Hotel | K28: Peaje | L28: Comida | M28: Totales
B29: LUNES | C29: ZONA 3 | H29: 43 | I29: =+H29/33*28 -> 36.484848 | L29: 50 | M29: =+I29+J29+K29+L29 -> 86.484848
B30: MARTES | C30: ZONA 3 | H30: 43 | I30: =+H30/33*28 -> 36.484848 | L30: 50 | M30: =+I30+J30+K30+L30 -> 86.484848
B31: MIERCOLES | C31: ZONA 10 Y LLANOS DEL PINAL | H31: 36 | I31: =+H31/33*28 -> 30.545455 | L31: 50 | M31: =+I31+J31+K31+L31 -> 80.545455
B32: JUEVES | C32: ZONA 8 Y 9 | H32: 29 | I32: =+H32/33*28 -> 24.606061 | L32: 50 | M32: =+I32+J32+K32+L32 -> 74.606061
B33: VIERNES | C33: LA ESPERANZA ZONA 4, SAN MATEO, CAJOLA | H33: 66 | I33: =+H33/33*28 -> 56 | L33: 50 | M33: =+I33+J33+K33+L33 -> 106
H34: =SUM(H29:H33) -> 217 | I34: =SUM(I29:I33) -> 184.12121 | J34: =SUM(J29:J33) -> 0 | K34: =SUM(K29:K33) -> 0 | L34: =SUM(L29:L33) -> 250 | M34: =SUM(M29:M33) -> 434.12121
B37: SEMANA 4 | H37: kilometro promedios recorridos | K37: =+H44 -> 328 | L37: =+K37/33 -> 9.9393939 | M37: =+L37*28 -> 278.30303
H38: Kilometros | I38: Costo Gasolina | J38: Hotel | K38: Peaje | L38: Comida | M38: Totales
B39: LUNES | C39: ZONA 6 Y 7 | H39: 32 | I39: =+H39/33*28 -> 27.151515 | L39: 50 | M39: =+I39+J39+K39+L39 -> 77.151515
B40: MARTES | C40: LA ESPERANZA ZONA 1 Y 2 | H40: 48 | I40: =+H40/33*28 -> 40.727273 | L40: 50 | M40: =+I40+J40+K40+L40 -> 90.727273
B41: MIERCOLES | C41: SAN JUAN OSTUNCALCO | H41: 58 | I41: =+H41/33*28 -> 49.212121 | L41: 50 | M41: =+I41+J41+K41+L41 -> 99.212121
B42: JUEVES | C42: SAN MIGUEL SIGUILA , SIBILIA,HITAN , CABRICAN | H42: 120 | I42: =+H42/33*28 -> 101.81818 | J42: 125 | L42: =50+35 -> 85 | M42: =+I42+J42+K42+L42 -> 311.81818
B43: VIERNES | C43: CONCEPCION CHIQUIRICHAPA SAN MARTIN CHILE VERDE | H43: 70 | I43: =+H43/33*28 -> 59.393939 | L43: =35+50 -> 85 | M43: =+I43+J43+K43+L43 -> 144.39394
H44: =SUM(H39:H43) -> 328 | I44: =SUM(I39:I43) -> 278.30303 | J44: =SUM(J39:J43) -> 125 | K44: =SUM(K39:K43) -> 0 | L44: =SUM(L39:L43) -> 320 | M44: =SUM(M39:M43) -> 723.30303
B46: Nota: | C46: Tomar en cuenta que cada monto asignado en los viaticos son exclusivamente para el concepto asignado, no pueden usarse en coceptos diferentes
C47: En caso que se reciba una sola factura por desayuno y habitacion debe venir desgosada por concepto
C48: Por aparte este viaticos serán revisados basados en el traquin que obligatoria debe reportar el usuario, en caso no se encuentrre datos en el traking
C49: y no se tenga reporte o explicación validad con anticipación los viaticos de ese no serán aplicados.
...

Sheet Ruta14
B2: PLANIFICACION SEMANAL
B3: VENDEDOR | C3: Edie Alfonso Natareno Calderón
B4: RUTA | C4: XELA ESTE O ESTE
B5: SUPERVISOR | C5: IVAN FLORES
B8: SEMANA 1 | H8: kilometro promedios recorridos | K8: =50+70+90+90+90+200 -> 590 | L8: =+K8/33 -> 17.878788 | M8: =+L8*28 -> 500.60606 | N8: 565
H9: Kilometros | I9: Costo Gasolina | J9: Hotel | K9: Peaje | L9: Comida | M9: Totales
B10: LUNES | C10: Monumento al migrante, Moreria, San Cristobal, San Andrés Xecul y 4 Caminos | H10: 47 | I10: =+H10/33*28 -> 39.878788 | L10: 50 | M10: =+I10+J10+K10+L10 -> 89.878788
B11: MARTES | C11: San Francisco, La Cumbre, Santa Maria y Momostenango | H11: 108 | I11: =+H11/33*28 -> 91.636364 | L11: 50 | M11: =+I11+J11+K11+L11 -> 141.63636
B12: MIERCOLES | C12: De 4 Camiones hasta Gobernación de Totonicapan | H12: 66 | I12: =+H12/33*28 -> 56 | L12: 50 | M12: =+I12+J12+K12+L12 -> 106
B13: JUEVES | C13: Totonicapan | H13: 66 | I13: =+H13/33*28 -> 56 | L13: 50 | M13: =+I13+J13+K13+L13 -> 106
B14: VIERNES | C14: Totonicapan, Nimasac y Pasac 1 | H14: 84 | I14: =+H14/33*28 -> 71.272727 | L14: 50 | M14: =+I14+J14+K14+L14 -> 121.27273
H15: =SUM(H10:H14) -> 371 | I15: =SUM(I10:I14) -> 314.78788 | J15: =SUM(J10:J14) -> 0 | K15: =SUM(K10:K14) -> 0 | L15: =SUM(L10:L14) -> 250 | M15: =SUM(M10:M14) -> 564.78788
B17: SEMANA 2 | H17: kilometro promedios recorridos | K17: 295 | L17: =+K17/33 -> 8.9393939 | M17: =+L17*28 -> 250.30303 | N17: 1205
H18: Kilometros | I18: Costo Gasolina | J18: Hotel | K18: Peaje | L18: Comida | M18: Totales
B19: LUNES | C19: Palestina, Chamac hasta San Pedro, Aldeas aledañas a estos lugares | H19: 80 | I19: =+H19/33*28 -> 67.878788 | J19: 125 | L19: =35+50 -> 85 | M19: =+I19+J19+K19+L19 -> 277.87879
B20: MARTES | C20: San Pedro y San Marcos | H20: 20 | I20: =+H20/33*28 -> 16.969697 | J20: 125 | L20: =35+35+50 -> 120 | M20: =+I20+J20+K20+L20 -> 261.9697
B21: MIERCOLES | C21: San Marcos | H21: 10 | I21: =+H21/33*28 -> 8.4848485 | J21: 125 | L21: =35+50+35 -> 120 | M21: =+I21+J21+K21+L21 -> 253.48485
B22: JUEVES | C22: San Marcos | H22: 10 | I22: =+H22/33*28 -> 8.4848485 | J22: 125 | L22: =35+50+35 -> 120 | M22: =+I22+J22+K22+L22 -> 253.48485
B23: VIERNES | C23: San Marcos - Retorno | H23: 100 | I23: =+H23/33*28 -> 84.848485 | L23: =50+35 -> 85 | M23: =+I23+J23+K23+L23 -> 169.84848
H24: =SUM(H19:H23) -> 220 | I24: =SUM(I19:I23) -> 186.66667 | J24: =SUM(J19:J23) -> 500 | K24: =SUM(K19:K23) -> 0 | L24: =SUM(L19:L23) -> 530 | M24: =SUM(M19:M23) -> 1216.6667
B26: SEMANA 3 | H26: kilometro promedios recorridos | K26: 620 | L26: =+K26/33 -> 18.787879 | M26: =+L26*28 -> 526.06061 | N26: 1420
H27: Kilometros | I27: Costo Gasolina | J27: Hotel | K27: Peaje | L27: Comida | M27: Totales
B28: LUNES | C28: San Marcos Esquipulas, San Rafael Pie de la Cuesta, El Tumbador, Rodeo | H28: 100 | I28: =+H28/33*28 -> 84.848485 | J28: 125 | L28: =35+50 -> 85 | M28: =+I28+J28+K28+L28 -> 294.84848
C29: San Pablo, Malacatán, aldeas aledañas a los lugares mencionados
B30: MARTES | C30: Malacatàn, san jose petacalapa , el carmen, santa ana | H30: 120 | I30: =+H30/33*28 -> 101.81818 | J30: 125 | L30: =35+50+35 -> 120 | M30: =+I30+J30+K30+L30 -> 346.81818
B31: MIERCOLES | C31: catarina, limones, ocos, tecun uman | H31: 80 | I31: =+H31/33*28 -> 67.878788 | J31: 125 | L31: =35+50+35 -> 120 | M31: =+I31+J31+K31+L31 -> 312.87879
B32: JUEVES | C32: tecun uman, pajapita | H32: 35 | I32: =+H32/33*28 -> 29.69697 | J32: 125 | L32: =35+50+35 -> 120 | M32: =+I32+J32+K32+L32 -> 274.69697
B33: VIERNES | C33: Tecùn Ùman parte 2, Nuevo Progreso, el sitio, zanjon san lorenzo | H33: 181 | I33: =+H33/33*28 -> 153.57576 | L33: =35+50 -> 85 | M33: =+I33+J33+K33+L33 -> 238.57576
H34: =SUM(H28:H33) -> 516 | I34: =SUM(I28:I33) -> 437.81818 | J34: =SUM(J28:J33) -> 500 | K34: =SUM(K28:K33) -> 0 | L34: =SUM(L28:L33) -> 530 | M34: =SUM(M28:M33) -> 1467.8182
B38: Nota: | C38: Tomar en cuenta que cada monto asignado en los viaticos son exclusivamente para el concepto asignado, no pueden usarse en coceptos diferentes
C39: En caso que se reciba una sola factura por desayuno y habitacion debe venir desgosada por concepto
C40: Por aparte este viaticos serán revisados basados en el traquin que obligatoria debe reportar el usuario, en caso no se encuentrre datos en el traking
C41: y no se tenga reporte o explicación validad con anticipación los viaticos de ese no serán aplicados.

Sheet Ruta12
B1: PLANIFICACION SEMANAL
B2: VENDEDOR | C2: WALTER HERNANDEZ
B3: RUTA | C3: XELA SUR
B4: SUPERVISOR | C4: IVAN FLORES | H4: Salida | I4: Coatepeque
B7: SEMANA 1 | H7: kilometro promedios recorridos | K7: =+H14 -> 259.3 | L7: =+K7/33 -> 7.8575758 | M7: =+L7*28 -> 220.01212
H8: Kilometros | I8: Costo Gasolina | J8: Hotel | K8: Peaje | L8: Comida | M8: Totales | N8: 1230
B9: LUNES | C9: MAZATENANGO | H9: 70 | I9: =+H9/33*28 -> 59.393939 | J9: 125 | L9: =35+50 -> 85 | M9: =+I9+J9+K9+L9 -> 269.39394
B10: MARTES | C10: SAN ANTONIO, SANTO TOMAS, SAN PABLO JOCOLOPILAS MAZATENANGO | H10: 35 | I10: =+H10/33*28 -> 29.69697 | J10: 125 | L10: =35+50+35 -> 120 | M10: =+I10+J10+K10+L10 -> 274.69697
B11: MIERCOLES | C11: CHICACAO, SAN MIGUEL PANAM, NAHUALATE , SAN JOSE EL IDOLO SAN BERNARDINO MAZATENANGO | H11: 76 | I11: =+H11/33*28 -> 64.484848 | J11: 125 | L11: =35+50+35 -> 120 | M11: =+I11+J11+K11+L11 -> 309.48485
B12: JUEVES | C12: MAZATENANGO, SAMAYAC, MAZATENANGO | H12: 20 | I12: =+H12/33*28 -> 16.969697 | J12: 125 | L12: =35+50+35 -> 120 | M12: =+I12+J12+K12+L12 -> 261.9697
B13: VIERNES | C13: San Felipe, San Martin, San Sebastián, Quetzaltenango | H13: 58.3 | I13: =+H13/33*28 -> 49.466667 | L13: =35+50 -> 85 | M13: =+I13+J13+K13+L13 -> 134.46667
H14: =SUM(H9:H13) -> 259.3 | I14: =SUM(I9:I13) -> 220.01212 | J14: =SUM(J9:J13) -> 500 | K14: =SUM(K9:K13) -> 0 | L14: =SUM(L9:L13) -> 530 | M14: =SUM(M9:M13) -> 1250.0121
B16: SEMANA 2 | H16: kilometro promedios recorridos | K16: =+H23 -> 363.2 | L16: =+K16/33 -> 11.006061 | M16: =+L16*28 -> 308.1697
H17: Kilometros | I17: Costo Gasolina | J17: Hotel | K17: Peaje | L17: Comida | M17: Totales | N17: 1330
B18: LUNES | C18: CUYOTENANGO, LA MAQUINA 1 Y 2, TULATE, REU | H18: 190 | I18: =+H18/33*28 -> 161.21212 | J18: 125 | L18: =35+50 -> 85 | M18: =+I18+J18+K18+L18 -> 371.21212
B19: MARTES | C19: RETALHULEU | H19: 2 | I19: =+H19/33*28 -> 1.6969697 | J19: 125 | L19: =35+50+35 -> 120 | M19: =+I19+J19+K19+L19 -> 246.69697
B20: MIERCOLES | C20: RETALHULEU | H20: 2 | I20: =+H20/33*28 -> 1.6969697 | J20: 125 | L20: =35+50+35 -> 120 | M20: =+I20+J20+K20+L20 -> 246.69697
B21: JUEVES | C21: CHAMPERICO, CABALLO BLANCO | H21: 74 | I21: =+H21/33*28 -> 62.787879 | J21: 125 | L21: =35+50+35 -> 120 | M21: =+I21+J21+K21+L21 -> 307.78788
B22: VIERNES | C22: NUEVO SAN CARLOS Y EL ASINTAL - Retorno | H22: 95.2 | I22: =+H22/33*28 -> 80.775758 | L22: =50+35 -> 85 | M22: =+I22+J22+K22+L22 -> 165.77576
H23: =SUM(H18:H22) -> 363.2 | I23: =SUM(I18:I22) -> 308.1697 | J23: =SUM(J18:J22) -> 500 | K23: =SUM(K18:K22) -> 0 | L23: =SUM(L18:L22) -> 530 | M23: =SUM(M18:M22) -> 1338.1697
B26: SEMANA 3 | H26: kilometro promedios recorridos | K26: =+H33 -> 278.6 | L26: =+K26/33 -> 8.4424242 | M26: =+L26*28 -> 236.38788
H27: Kilometros | I27: Costo Gasolina | J27: Hotel | K27: Peaje | L27: Comida | M27: Totales | N27: 1280
B28: LUNES | C28: QUETZALTENANGO, CONCEPCION, SAN MARTIN CHILE VERDE COLOMBA COATEPQUE | H28: 63 | I28: =+H28/33*28 -> 53.454545 | J28: 0 | L28: 50 | M28: =+I28+J28+K28+L28 -> 103.45455
B29: MARTES | C29: COATEPEQUE | H29: 3 | I29: =+H29/33*28 -> 2.5454545 | J29: 0 | L29: 50 | M29: =+I29+J29+K29+L29 -> 52.545455
B30: MIERCOLES | C30: COATEPEQUE, LA UNION, LAS PALMAS | H30: 45 | I30: =+H30/33*28 -> 38.181818 | J30: 0 | L30: 50 | M30: =+I30+J30+K30+L30 -> 88.181818
B31: JUEVES | C31: COATEPEQUE, SIBANA, XAB, FLORES GENOVA, RETALHULEU | H31: 92.6 | I31: =+H31/33*28 -> 78.569697 | J31: 0 | L31: 50 | M31: =+I31+J31+K31+L31 -> 128.5697
B32: VIERNES | C32: REU, SANTA CRUZ MULUA, SAN MARTIN ZAPOTITLAN, QUETZALTENANGO | H32: 75 | I32: =+H32/33*28 -> 63.636364 | L32: =50+35 -> 85 | M32: =+I32+J32+K32+L32 -> 148.63636
H33: =SUM(H28:H32) -> 278.6 | I33: =SUM(I28:I32) -> 236.38788 | J33: =SUM(J28:J32) -> 0 | K33: =SUM(K28:K32) -> 0 | L33: =SUM(L28:L32) -> 285 | M33: =SUM(M28:M32) -> 521.38788
B36: Nota: | C36: Tomar en cuenta que cada monto asignado en los viaticos son exclusivamente para el concepto asignado, no pueden usarse en coceptos diferentes
C37: En caso que se reciba una sola factura por desayuno y habitacion debe venir desgosada por concepto
C38: Por aparte este viaticos serán revisados basados en el traquin que obligatoria debe reportar el usuario, en caso no se encuentrre datos en el traking
C39: y no se tenga reporte o explicación validad con anticipación los viaticos de ese no serán aplicados.

Sheet Ruta13
B2: PLANIFICACION SEMANAL
B3: VENDEDOR | C3: pendiente
B4: RUTA | C4: Xela nor oriente
B5: SUPERVISOR | C5: IVAN FLORES
B10: SEMANA 1----HUEHUETENANGO | H10: kilometro promedios recorridos | K10: 680 | L10: =+K10/33 -> 20.606061 | M10: =+L10*28 -> 576.9697 | N10: 1325
H11: Kilometros | I11: Costo Gasolina | J11: Hotel | K11: Peaje | L11: Comida | M11: Totales
B12: LUNES | C12: Rancho de Teja, Pologua, Tierra Blanca, Chiquival, Estancia de la Virgen | H12: 90 | I12: =+H12/33*28 -> 76.363636 | J12: 125 | L12: =35+50 -> 85 | M12: =+I12+J12+K12+L12 -> 286.36364
B13: MARTES | C13: Malacantancito, San Lorenzo 1, Ojechejel, Terminal y Zona 5 | H13: 35 | I13: =+H13/33*28 -> 29.69697 | J13: 125 | L13: =35+50+35 -> 120 | M13: =+I13+J13+K13+L13 -> 274.69697
B14: MIERCOLES | C14: Cambote Sectores 1 y 2, Chimusinique | H14: 20 | I14: =+H14/33*28 -> 16.969697 | J14: 125 | L14: =35+50+35 -> 120 | M14: =+I14+J14+K14+L14 -> 261.9697
B15: JUEVES | C15: Cambote Sectores 3,4,5,6,7 | H15: 20 | I15: =+H15/33*28 -> 16.969697 | J15: 125 | L15: =35+50+35 -> 120 | M15: =+I15+J15+K15+L15 -> 261.9697
B16: VIERNES | C16: Chinaca, Chiantla, Aguacatan | H16: 155 | I16: =+H16/33*28 -> 131.51515 | L16: =50+35 -> 85 | M16: =+I16+J16+K16+L16 -> 216.51515
H17: =SUM(H12:H16) -> 320 | I17: =SUM(I12:I16) -> 271.51515 | J17: =SUM(J12:J16) -> 500 | K17: =SUM(K12:K16) -> 0 | L17: =SUM(L12:L16) -> 530 | M17: =SUM(M12:M16) -> 1301.5152
B20: SEMANA 2----HUEHUETENANGO | H20: kilometro promedios recorridos | K20: 680 | L20: =+K20/33 -> 20.606061 | M20: =+L20*28 -> 576.9697 | N20: 1579
H21: Kilometros | I21: Costo Gasolina | J21: Hotel | K21: Peaje | L21: Comida | M21: Totales
B22: LUNES | C22: San Sebastian, Colotenango, Ixtahuacan, Cuilco | H22: 155 | I22: =+H22/33*28 -> 131.51515 | J22: 125 | L22: =35+50 -> 85 | M22: =+I22+J22+K22+L22 -> 341.51515
B23: MARTES | C23: San Pedro Necta, El Cable, Cambojayito, Camoja | H23: 98 | I23: =+H23/33*28 -> 83.151515 | J23: 125 | L23: =35+50+35 -> 120 | M23: =+I23+J23+K23+L23 -> 328.15152
B24: MIERCOLES | C24: La Democracia, Sta. Rosa de Lima, La Mesilla | H24: 170 | I24: =+H24/33*28 -> 144.24242 | J24: 125 | L24: =35+50+35 -> 120 | M24: =+I24+J24+K24+L24 -> 389.24242
B25: JUEVES | C25: Cuatro Caminos, Nenton, Sta. Ana | H25: 90 | I25: =+H25/33*28 -> 76.363636 | J25: 125 | L25: =35+50+35 -> 120 | M25: =+I25+J25+K25+L25 -> 321.36364
B26: VIERNES | C26: San Antonio, Jacaltenango - Retorno | H26: 160 | I26: =+H26/33*28 -> 135.75758 | L26: =35+50 -> 85 | M26: =+I26+J26+K26+L26 -> 220.75758
H27: =SUM(H22:H26) -> 673 | I27: =SUM(I22:I26) -> 571.0303 | J27: =SUM(J22:J26) -> 500 | K27: =SUM(K22:K26) -> 0 | L27: =SUM(L22:L26) -> 530 | M27: =SUM(M22:M26) -> 1601.0303
B35: SEMANA 3era----SOLOLÁ | H35: kilometro promedios recorridos | K35: =610+190 -> 800 | L35: =+K35/33 -> 24.242424 | M35: =+L35*28 -> 678.78788 | N35: 1473
H36: Kilometros | I36: Costo Gasolina | J36: Hotel | K36: Peaje | L36: Comida | M36: Totales
B37: LUNES | C37: Nahuala, San Juan, Santa Cruz y Santa Clara La Laguna | H37: 85 | I37: =+H37/33*28 -> 72.121212 | J37: 125 | L37: =35+50 -> 85 | M37: =+I37+J37+K37+L37 -> 282.12121
B38: MARTES | C38: San Pedro La Laguna, El Novillero Ruta Interamericana hasta los Encuentros | H38: 96 | I38: =+H38/33*28 -> 81.454545 | J38: 125 | L38: =35+50+35 -> 120 | M38: =+I38+J38+K38+L38 -> 326.45455
B39: MIERCOLES | C39: Las Trampas, Aldea Las Canoas, Godinez, San Lucas, Santiago Atitlàn | H39: 88 | I39: =+H39/33*28 -> 74.666667 | J39: 125 | L39: =35+50+35 -> 120 | M39: =+I39+J39+K39+L39 -> 319.66667
B40: JUEVES | C40: Sololà Centro, Concepciòn, Aldea Las Margaritas | H40: 91 | I40: =+H40/33*28 -> 77.212121 | J40: 125 | L40: =35+50+35 -> 120 | M40: =+I40+J40+K40+L40 -> 322.21212
B41: VIERNES | C41: Panajachel, El Tablòn, San Lucìa Utatlàn-Chupol, Chichicastenango -Retorno | H41: 120 | I41: =+H41/33*28 -> 101.81818 | L41: =35+50 -> 85 | M41: =+I41+J41+K41+L41 -> 186.81818
H42: =SUM(H37:H41) -> 480 | I42: =SUM(I37:I41) -> 407.27273 | J42: =SUM(J37:J41) -> 500 | K42: =SUM(K37:K41) -> 0 | L42: =SUM(L37:L41) -> 530 | M42: =SUM(M37:M41) -> 1437.2727
B45: SEMANA 4----QUICHÉ | H45: kilometro promedios recorridos | K45: 700 | L45: =+K45/33 -> 21.212121 | M45: =+L45*28 -> 593.93939 | N45: 1485
H46: Kilometros | I46: Costo Gasolina | J46: Hotel | K46: Peaje | L46: Comida | M46: Totales
B47: LUNES | C47: SACAPULAS CUNEN USPANTAN UNO | H47: 145 | I47: =+H47/33*28 -> 123.0303 | J47: 125 | L47: =35+50 -> 85 | M47: =+I47+J47+K47+L47 -> 333.0303
B48: MARTES | C48: USPANTAN DOS NEBAJ SAN PEDRO JOCOPILAS | H48: 130 | I48: =+H48/33*28 -> 110.30303 | J48: 125 | L48: =35+50+35 -> 120 | M48: =+I48+J48+K48+L48 -> 355.30303
B49: MIERCOLES | C49: CHICHE CHINIQUE ZACUALPA JOYABAJ | H49: 109 | I49: =+H49/33*28 -> 92.484848 | J49: 125 | L49: =35+50+35 -> 120 | M49: =+I49+J49+K49+L49 -> 337.48485
B50: JUEVES | C50: SAN ANTONIO ILOTENAGO ZONA 4 TERMINAL, | H50: 38 | I50: =+H50/33*28 -> 32.242424 | J50: 125 | L50: =35+50+35 -> 120 | M50: =+I50+J50+K50+L50 -> 277.24242
B51: VIERNES | C51: QUICHE ZONAS 1, 2, 3,5, - Retorno | H51: 114 | I51: =+H51/33*28 -> 96.727273 | L51: =35+50 -> 85 | M51: =+I51+J51+K51+L51 -> 181.72727
H52: =SUM(H47:H51) -> 536 | I52: =SUM(I47:I51) -> 454.78788 | J52: =SUM(J47:J51) -> 500 | K52: =SUM(K47:K51) -> 0 | L52: =SUM(L47:L51) -> 530 | M52: =SUM(M47:M51) -> 1484.7879
B55: Nota: | C55: Tomar en cuenta que cada monto asignado en los viaticos son exclusivamente para el concepto asignado, no pueden usarse en coceptos diferentes
C56: En caso que se reciba una sola factura por desayuno y habitacion debe venir desgosada por concepto
C57: Por aparte este viaticos serán revisados basados en el traquin que obligatoria debe reportar el usuario, en caso no se encuentrre datos en el traking
C58: y no se tenga reporte o explicación validad con anticipación los viaticos de ese no serán aplicados.

Sheet TABLA DE VIATICOS
C3: SEMANA 1 | D3: SEMANA 2 | E3: SEMANA 3 | F3: SEMANA 4
B4: MICHAEL CILAS | C4: =+Ruta13!N10 -> 1325 | D4: =+Ruta13!N20 -> 1579 | E4: =+Ruta13!N35 -> 1473 | F4: =+Ruta13!N45 -> 1485
B5: WALTER HERNANDEZ | C5: =+Ruta12!N8 -> 1230 | D5: =+Ruta12!N17 -> 1330 | E5: =+Ruta12!N27 -> 1280 | F5: =+C5 -> 1230
B6: MARVIN COLOP | C6: =+Ruta10!M14 -> 338.30303 | D6: =+Ruta10!M24 -> 310.30303 | E6: =+Ruta10!M34 -> 434.12121 | F6: =+Ruta10!M44 -> 723.30303
B7: EDIE NATARENO | C7: 465 | D7: 925 | E7: 1165 | F7: 465
B8: SUPERVISOR | C8: 0 | D8: 0 | E8: 0 | F8: 0
C9: =SUM(C4:C8) -> 3358.303 | D9: =SUM(D4:D8) -> 4144.303 | E9: =SUM(E4:E8) -> 4352.1212 | F9: =SUM(F4:F8) -> 3903.303
B11: SALDO | C11: =8000-C9 -> 4641.697 | D11: =8000-D9 -> 3855.697 | E11: =8000-E9 -> 3647.8788 | F11: =8000-F9 -> 4096.697

Sheet SUPERVISOR
B2: PLANIFICACION SEMANAL
B3: VENDEDOR | C3: FRANCISCO JAVIER SALAZAR
B4: RUTA | C4: XELA SUR
B5: SUPERVISOR | C5: EDIE NATARENO
B8: SEMANA 1 | H8: kilometro promedios recorridos | K8: =+H15 -> 190 | L8: =+K8/33 -> 5.7575758 | M8: =+L8*28 -> 161.21212
H9: Kilometros | I9: Costo Gasolina | J9: Hotel | K9: Peaje | L9: Comida | M9: Totales | N9: 950
B10: LUNES | C10: TECUN UMAN | H10: =95*2 -> 190 | I10: =+H10/33*28 -> 161.21212 | J10: 100 | L10: 55 | M10: =+I10+J10+K10+L10 -> 316.21212
B11: MARTES | I11: =+H11/33*28 -> 0 | J11: 100 | L11: 80 | M11: =+I11+J11+K11+L11 -> 180
B12: MIERCOLES | I12: =+H12/33*28 -> 0 | J12: 100 | L12: 80 | M12: =+I12+J12+K12+L12 -> 180
B13: JUEVES | I13: =+H13/33*28 -> 0 | J13: 100 | L13: 80 | M13: =+I13+J13+K13+L13 -> 180
B14: VIERNES | I14: =+H14/33*28 -> 0 | L14: 55 | M14: =+I14+J14+K14+L14 -> 55
H15: =SUM(H10:H14) -> 190 | I15: =SUM(I10:I14) -> 161.21212 | J15: =SUM(J10:J14) -> 400 | K15: =SUM(K10:K14) -> 0 | L15: =SUM(L10:L14) -> 350 | M15: =SUM(M10:M14) -> 911.21212
B18: IVAN FLORES/SUPERVISOR
B19: SEMANA 1----HUEHUETENANGO | H19: kilometro promedios recorridos | K19: 680 | L19: =+K19/33 -> 20.606061 | M19: =+L19*28 -> 576.9697 | N19: 1100
H20: Kilometros | I20: Costo Gasolina | J20: Hotel | K20: Peaje | L20: Comida | M20: Totales
B21: VIERNES | C21: TOTONICAPAN | I21: =+H21/33*28 -> 0 | M21: =+I21+J21+K21+L21 -> 0
I22: =+H22/33*28 -> 0 | M22: =+I22+J22+K22+L22 -> 0
I23: =+H23/33*28 -> 0 | M23: =+I23+J23+K23+L23 -> 0
I24: =+H24/33*28 -> 0 | M24: =+I24+J24+K24+L24 -> 0
I25: =+H25/33*28 -> 0 | M25: =+I25+J25+K25+L25 -> 0
H26: =SUM(H21:H25) -> 0 | I26: =SUM(I21:I25) -> 0 | J26: =SUM(J21:J25) -> 0 | K26: =SUM(K21:K25) -> 0 | L26: =SUM(L21:L25) -> 0 | M26: =SUM(M21:M25) -> 0

Sheet VIATICOS DE LA SEMANA 
A3: JUAN CARLOS
A4: SEMANA 4----QUICHÉ | G4: kilometro promedios recorridos | J4: 700 | K4: =+J4/33 -> 21.212121 | L4: =+K4*28 -> 593.93939 | M4: 930
G5: Kilometros | H5: Costo Gasolina | I5: Hotel | J5: Peaje | K5: Comida | L5: Totales
A6: LUNES | B6: SACAPULAS CUNEN USPANTAN UNO | G6: 145 | H6: =+G6/33*28 -> 123.0303 | L6: =+H6+I6+J6+K6 -> 123.0303
A7: MARTES | B7: USPANTAN DOS NEBAJ SAN PEDRO JOCOPILAS | H7: =+G7/33*28 -> 0 | L7: =+H7+I7+J7+K7 -> 0
A8: MIERCOLES | B8: CHICHE CHINIQUE ZACUALPA JOYABAJ | G8: 109 | H8: =+G8/33*28 -> 92.484848 | I8: 100 | K8: 80 | L8: =+H8+I8+J8+K8 -> 272.48485
A9: JUEVES | B9: SAN ANTONIO ILOTENAGO ZONA 4 TERMINAL, | G9: 38 | H9: =+G9/33*28 -> 32.242424 | I9: 100 | K9: 80 | L9: =+H9+I9+J9+K9 -> 212.24242
A10: VIERNES | B10: QUICHE ZONAS 1, 2, 3,5, CHICHICASTENANGO | G10: 114 | H10: =+G10/33*28 -> 96.727273 | K10: 55 | L10: =+H10+I10+J10+K10 -> 151.72727
G11: =SUM(G6:G10) -> 406 | H11: =SUM(H6:H10) -> 344.48485 | I11: =SUM(I6:I10) -> 200 | J11: =SUM(J6:J10) -> 0 | K11: =SUM(K6:K10) -> 215 | L11: =SUM(L6:L10) -> 759.48485 | M11: =+L11-200 -> 559.48485
D14: ALLAN SANTOS
A15: SEMANA 3 | G15: kilometro promedios recorridos | J15: =+G22 -> 57.9 | K15: =+J15/33 -> 1.7545455 | L15: =+K15*28 -> 49.127273 | M15: 140
G16: Kilometros | H16: Costo Gasolina | I16: Hotel | J16: Peaje | K16: Comida | L16: Totales
A17: LUNES | B17: ZONA 3 | G17: 1.5 | H17: =+G17/33*28 -> 1.2727273 | L17: =+H17+I17+J17+K17 -> 1.2727273
A19: MIERCOLES | B19: ZONA 8 Y 9 | G19: 3 | H19: =+G19/33*28 -> 2.5454545 | K19: 30 | L19: =+H19+I19+J19+K19 -> 32.545455
A20: JUEVES | B20: ZONA 10 Y LLANOS DEL PINAL | G20: =10.2*2 -> 20.4 | H20: =+G20/33*28 -> 17.309091 | K20: 30 | L20: =+H20+I20+J20+K20 -> 47.309091
A21: VIERNES | B21: LA ESPERANZA ZONA 4, SAN MATEO, CAJOLA | G21: =16.5*2 -> 33 | H21: =+G21/33*28 -> 28 | K21: 30 | L21: =+H21+I21+J21+K21 -> 58
G22: =SUM(G17:G21) -> 57.9 | H22: =SUM(H17:H21) -> 49.127273 | I22: =SUM(I17:I21) -> 0 | J22: =SUM(J17:J21) -> 0 | K22: =SUM(K17:K21) -> 90 | L22: =SUM(L17:L21) -> 139.12727
C25: EDIE NATARENO
A26: SEMANA 1 | G26: kilometro promedios recorridos | J26: =50+70+90+90+90+200 -> 590 | K26: =+J26/33 -> 17.878788 | L26: =+K26*28 -> 500.60606 | M26: 465
G27: Kilometros | H27: Costo Gasolina | I27: Hotel | J27: Peaje | K27: Comida | L27: Totales
A28: LUNES | B28: Monumento al migrante, Moreria, San Cristobal, San Andrés Xecul y 4 Caminos | G28: 47 | H28: =+G28/33*28 -> 39.878788 | K28: 30 | L28: =+H28+I28+J28+K28 -> 69.878788
A29: MARTES | B29: San Francisco, La Cumbre, Santa Maria y Momostenango | G29: 108 | H29: =+G29/33*28 -> 91.636364 | K29: 30 | L29: =+H29+I29+J29+K29 -> 121.63636
A30: MIERCOLES | B30: De 4 Camiones hasta Gobernación de Totonicapan | G30: 66 | H30: =+G30/33*28 -> 56 | K30: 30 | L30: =+H30+I30+J30+K30 -> 86
A31: JUEVES | B31: Totonicapan | G31: 66 | H31: =+G31/33*28 -> 56 | K31: 30 | L31: =+H31+I31+J31+K31 -> 86
L32: =+H32+I32+J32+K32 -> 0
G33: =SUM(G28:G32) -> 287 | H33: =SUM(H28:H32) -> 243.51515 | I33: =SUM(I28:I32) -> 0 | J33: =SUM(J28:J32) -> 0 | K33: =SUM(K28:K32) -> 120 | L33: =SUM(L28:L32) -> 363.51515 | M33: 93
M34: =465-M33 -> 372
A37: SEMANA 3 | G37: kilometro promedios recorridos | J37: =+G44 -> 412.5 | K37: =+J37/33 -> 12.5 | L37: =+K37*28 -> 350
G38: Kilometros | H38: Costo Gasolina | I38: Hotel | J38: Peaje | K38: Comida | L38: Totales
A39: LUNES | B39: QUETZALTENANGO, CONCEPCION, SAN MARTIN CHILE VERDE COLOMBA COATEPQUE | G39: 63 | H39: =+G39/33*28 -> 53.454545 | I39: 100 | K39: 55 | L39: =+H39+I39+J39+K39 -> 208.45455
A40: MARTES | B40: COATEPEQUE-XELA-COATEPEQUE | G40: =59.1*2 -> 118.2 | H40: =+G40/33*28 -> 100.29091 | K40: 25 | L40: =+H40+I40+J40+K40 -> 125.29091
A41: MIERCOLES | B41: COATEPEQUE, LA UNION, LAS PALMAS | G41: 83 | H41: =+G41/33*28 -> 70.424242 | I41: 100 | K41: 80 | L41: =+H41+I41+J41+K41 -> 250.42424
A42: JUEVES | B42: COATEPEQUE, SIBANA, XAB, FLORES GENOVA, RETALHULEU | G42: 92.6 | H42: =+G42/33*28 -> 78.569697 | I42: 100 | K42: 80 | L42: =+H42+I42+J42+K42 -> 258.5697
A43: VIERNES | B43: REU, SANTA CRUZ MULUA, SAN MARTIN ZAPOTITLAN, QUETZALTENANGO | G43: 55.7 | H43: =+G43/33*28 -> 47.260606 | K43: 55 | L43: =+H43+I43+J43+K43 -> 102.26061
G44: =SUM(G39:G43) -> 412.5 | H44: =SUM(H39:H43) -> 350 | I44: =SUM(I39:I43) -> 300 | J44: =SUM(J39:J43) -> 0 | K44: =SUM(K39:K43) -> 295 | L44: =SUM(L39:L43) -> 945
A49: SEMANA 3 | G49: kilometro promedios recorridos | J49: =+G56 -> 203.3 | K49: =+J49/33 -> 6.1606061 | L49: =+K49*28 -> 172.49697
G50: Kilometros | H50: Costo Gasolina | I50: Hotel | J50: Peaje | K50: Comida | L50: Totales
A51: LUNES | B51: TOTONICAPAN SALIDA A QUICHE TOTO CENTRO CHUJUYUP | H51: =+G51/33*28 -> 0 | K51: 30 | L51: =+H51+I51+J51+K51 -> 30
A52: MARTES | H52: =+G52/33*28 -> 0 | L52: =+H52+I52+J52+K52 -> 0
A53: MIERCOLES | B53: SANTA MARÍA CHIQUIMULA MOMOSTENANGO SAN FRANCISCO ZONA 3 XELA | G53: 109 | H53: =+G53/33*28 -> 92.484848 | K53: 30 | L53: =+H53+I53+J53+K53 -> 122.48485
...

Sheet viaciones
A1: DIAS GOZADOS DE PERIODO VACIONAL /MARZO 2020 | I1: 43922
A2: NOMBRE/DIAS | B2: martes | C2: lunes | D2: martes | E2: miércoles | F2: jueves | G2: viernes | H2: sabado | I2: Lunes | J2: Martes | K2: Miercoles | L2: TOTAL
B3: 17 | C3: 23 | D3: 24 | E3: 25 | F3: 26 | G3: 27 | H3: 28 | I3: 6 | J3: 7 | K3: 8
A4: Ivan | C4: 1 | D4: 1 | E4: 1 | F4: 1 | G4: 1 | H4: 1 | L4: =SUM(B4:K4) -> 6
A5: Edie | B5: 1 | C5: 1 | D5: 1 | E5: 1 | F5: 1 | G5: 1 | I5: 1 | J5: 1 | K5: 0.5 | L5: =SUM(B5:K5) -> 8.5
A6: Allan | B6: 1 | C6: 1 | D6: 1 | E6: 1 | F6: 1 | G6: 1 | H6: 1 | L6: =SUM(B6:K6) -> 7
A7: Javier | B7: 1 | C7: 1 | D7: 1 | E7: 1 | F7: 1 | G7: 1 | I7: 1 | J7: 1 | K7: 0.5 | L7: =SUM(B7:K7) -> 8.5
A8: Juan Carlos | B8: 1 | C8: 1 | D8: 1 | E8: 1 | F8: 1 | G8: 1 | H8: 1 | I8: 1 | J8: 1 | K8: 0.5 | L8: =SUM(B8:K8) -> 9.5
